<?xml version="1.0" ?>
<!-- =================================================================================== -->
<!-- |    This document was autogenerated by xacro from biped.urdf.xacro               | -->
<!-- |    EDITING THIS FILE BY HAND IS NOT RECOMMENDED                                 | -->
<!-- =================================================================================== -->
<robot name="bipedal_robot">
  <link name="base_link">
    <inertial>
      <origin rpy="0 0 0" xyz="0.0000000 -0.0001528 -0.0041040"/>
      <mass value="2.0725291"/>
      <inertia ixx="0.0145041" ixy="0.0000000" ixz="0.0000000" iyy="0.0118815" iyz="0.0000062" izz="0.0059465"/>
    </inertial>
    <visual>
      <origin rpy="0 0 0" xyz="0 0 0"/>
      <geometry>
        <mesh filename="package://biped_description/meshes/base_link.STL"/>
      </geometry>
      <material name="">
        <color rgba="1 1 1 1"/>
      </material>
    </visual>
    <collision>
      <origin rpy="0 0 0" xyz="0 0 0"/>
      <geometry>
        <mesh filename="package://biped_description/meshes/base_link.STL"/>
      </geometry>
    </collision>
  </link>
  <link name="imu_link">
    <inertial>
      <mass value="0.001"/>
      <origin rpy="0 0 0" xyz="0 0 0"/>
      <inertia ixx="0.0001" ixy="0" ixz="0" iyy="0.0001" iyz="0" izz="0.0001"/>
    </inertial>
    <visual>
      <origin rpy="0 0 0" xyz="0 0 0"/>
      <geometry>
        <box size="0.04 0.04 0.01"/>
      </geometry>
      <material name="imu_red">
        <color rgba="1.0 0.0 0.0 1.0"/>
      </material>
    </visual>
  </link>
  <joint name="imu_joint" type="fixed">
    <parent link="base_link"/>
    <child link="imu_link"/>
    <origin rpy="0.0 0.0 0.0" xyz="0.0 0.0 0.05"/>
  </joint>
  <link name="left_hip_pitch_link">
    <inertial>
      <origin rpy="0 0 0" xyz="-0.0023863 0.0000000 0.0511609"/>
      <mass value="0.4380000"/>
      <inertia ixx="0.0003894" ixy="0.0000000" ixz="0.0000025" iyy="0.0002773" iyz="0.0000000" izz="0.0002167"/>
    </inertial>
    <visual>
      <origin rpy="0 0 0" xyz="0 0 0"/>
      <geometry>
        <mesh filename="package://biped_description/meshes/left_hip_pitch_link.STL"/>
      </geometry>
      <material name="">
        <color rgba="1 1 1 1"/>
      </material>
    </visual>
    <collision>
      <origin rpy="0 0 0" xyz="0 0 0"/>
      <geometry>
        <mesh filename="package://biped_description/meshes/left_hip_pitch_link.STL"/>
      </geometry>
    </collision>
  </link>
  <joint name="left_hip_pitch_joint" type="revolute">
    <origin rpy="-1.5708 3.1416 0" xyz="0 0.049 -0.067"/>
    <parent link="base_link"/>
    <child link="left_hip_pitch_link"/>
    <axis xyz="0 0 -1"/>
    <limit effort="10" lower="-1.57" upper="1.57" velocity="20"/>
  </joint>
  <link name="left_hip_roll_link">
    <inertial>
      <origin rpy="0 0 0" xyz="0.0054951 -0.1648534 -0.0187913"/>
      <mass value="0.5673275"/>
      <inertia ixx="0.0025730" ixy="0.0001006" ixz="0.0000001" iyy="0.0003215" iyz="-0.0001472" izz="0.0024395"/>
    </inertial>
    <visual>
      <origin rpy="0 0 0" xyz="0 0 0"/>
      <geometry>
        <mesh filename="package://biped_description/meshes/left_hip_roll_link.STL"/>
      </geometry>
      <material name="">
        <color rgba="1 1 1 1"/>
      </material>
    </visual>
    <collision>
      <origin rpy="0 0 0" xyz="0 0 0"/>
      <geometry>
        <mesh filename="package://biped_description/meshes/left_hip_roll_link.STL"/>
      </geometry>
    </collision>
  </link>
  <joint name="left_hip_roll_joint" type="revolute">
    <origin rpy="0 -1.5708 0" xyz="-0.0205 0 0.055"/>
    <parent link="left_hip_pitch_link"/>
    <child link="left_hip_roll_link"/>
    <axis xyz="0 0 -1"/>
    <limit effort="10" lower="-1.57" upper="0.4" velocity="20"/>
  </joint>
  <link name="left_knee_link">
    <inertial>
      <origin rpy="0 0 0" xyz="-0.0037521 -0.1716951 -0.0213662"/>
      <mass value="0.2830000"/>
      <inertia ixx="0.0024385" ixy="-0.0000882" ixz="0.0000021" iyy="0.0001204" iyz="-0.0001394" izz="0.0024510"/>
    </inertial>
    <visual>
      <origin rpy="0 0 0" xyz="0 0 0"/>
      <geometry>
        <mesh filename="package://biped_description/meshes/left_knee_link.STL"/>
      </geometry>
      <material name="">
        <color rgba="1 1 1 1"/>
      </material>
    </visual>
    <collision>
      <origin rpy="0 0 0" xyz="0 0 0"/>
      <geometry>
        <mesh filename="package://biped_description/meshes/left_knee_link.STL"/>
      </geometry>
    </collision>
    <!-- <visual>
      <origin xyz="0 0 -0.05" rpy="0 0 0" />
      <geometry>
        <box size="0.08 0.04 0.02" />
      </geometry>
      <material name="shoe_black">
        <color rgba="0.9 0.9 0.1 1.0" />
      </material>
    </visual> -->
  </link>
  <joint name="left_knee_joint" type="revolute">
    <origin rpy="0 1.5708 0" xyz="0.0255 -0.2 -0.0205"/>
    <parent link="left_hip_roll_link"/>
    <child link="left_knee_link"/>
    <axis xyz="0 0 1"/>
    <limit effort="10" lower="-0.2" upper="2.2" velocity="20"/>
  </joint>
  <link name="right_hip_pitch_link">
    <inertial>
      <origin rpy="0 0 0" xyz="-0.0023863 0.0000000 0.0511609"/>
      <mass value="0.4380000"/>
      <inertia ixx="0.0003894" ixy="0.0000000" ixz="0.0000025" iyy="0.0002773" iyz="0.0000000" izz="0.0002167"/>
    </inertial>
    <visual>
      <origin rpy="0 0 0" xyz="0 0 0"/>
      <geometry>
        <mesh filename="package://biped_description/meshes/right_hip_pitch_link.STL"/>
      </geometry>
      <material name="">
        <color rgba="1 1 1 1"/>
      </material>
    </visual>
    <collision>
      <origin rpy="0 0 0" xyz="0 0 0"/>
      <geometry>
        <mesh filename="package://biped_description/meshes/right_hip_pitch_link.STL"/>
      </geometry>
    </collision>
  </link>
  <joint name="right_hip_pitch_joint" type="revolute">
    <origin rpy="-1.5707963267949 0 3.14159265358979" xyz="0 -0.049 -0.067"/>
    <parent link="base_link"/>
    <child link="right_hip_pitch_link"/>
    <axis xyz="0 0 -1"/>
    <limit effort="10" lower="-1.57" upper="1.57" velocity="20"/>
  </joint>
  <link name="right_hip_roll_link">
    <inertial>
      <origin rpy="0 0 0" xyz="-0.0054951 -0.1648534 -0.0187913"/>
      <mass value="0.5673275"/>
      <inertia ixx="0.0025730" ixy="-0.0001006" ixz="-0.0000105" iyy="0.0003215" iyz="-0.0001472" izz="0.0024395"/>
    </inertial>
    <visual>
      <origin rpy="0 0 0" xyz="0 0 0"/>
      <geometry>
        <mesh filename="package://biped_description/meshes/right_hip_roll_link.STL"/>
      </geometry>
      <material name="">
        <color rgba="1 1 1 1"/>
      </material>
    </visual>
    <collision>
      <origin rpy="0 0 0" xyz="0 0 0"/>
      <geometry>
        <mesh filename="package://biped_description/meshes/right_hip_roll_link.STL"/>
      </geometry>
    </collision>
  </link>
  <joint name="right_hip_roll_joint" type="revolute">
    <origin rpy="3.1416 1.5708 0" xyz="-0.0205 0 0.055"/>
    <parent link="right_hip_pitch_link"/>
    <child link="right_hip_roll_link"/>
    <axis xyz="0 0 -1"/>
    <limit effort="10" lower="-0.4" upper="1.57" velocity="20"/>
  </joint>
  <link name="right_knee_link">
    <inertial>
      <origin rpy="0 0 0" xyz="0.0037519 -0.1716952 -0.0213662"/>
      <mass value="0.2830000"/>
      <inertia ixx="0.0024385" ixy="0.0000882" ixz="0.0000074" iyy="0.0001204" iyz="-0.0001394" izz="0.0024510"/>
    </inertial>
    <visual>
      <origin rpy="0 0 0" xyz="0 0 0"/>
      <geometry>
        <mesh filename="package://biped_description/meshes/right_knee_link.STL"/>
      </geometry>
      <material name="">
        <color rgba="1 1 1 1"/>
      </material>
    </visual>
    <collision>
      <origin rpy="0 0 0" xyz="0 0 0"/>
      <geometry>
        <mesh filename="package://biped_description/meshes/right_knee_link.STL"/>
      </geometry>
    </collision>
    <!-- <visual>
      <origin xyz="0 0 -0.05" rpy="0 0 0" />
      <geometry>
        <box size="0.08 0.04 0.02" />
      </geometry>
      <material name="shoe_black">
        <color rgba="0.9 0.9 0.1 1.0" />
      </material>
    </visual> -->
  </link>
  <joint name="right_knee_joint" type="revolute">
    <origin rpy="0 -1.5708 0" xyz="-0.0255 -0.2 -0.0205"/>
    <parent link="right_hip_roll_link"/>
    <child link="right_knee_link"/>
    <axis xyz="0 0 1"/>
    <limit effort="10" lower="-2.2" upper="0.2" velocity="20"/>
  </joint>
</robot>
